2025-09-16 17:06:39	WARN	sdimaging::::casa	The sdimaging task is deprecated and will be removed in future releases. Please use tsdimaging instead.
2025-09-16 17:06:39	SEVERE	sdimaging::::casa	Traceback (most recent call last):
2025-09-16 17:06:39	SEVERE	sdimaging::::casa+	             ^^^^^^^^^^^^^^^^^^^^^
2025-09-16 17:06:39	SEVERE	sdimaging::::casa+	  File "/scratch/scastro/casa/Tests/reports/casa-6.7.2-15-py3.12.el8/lib/py/lib/python3.12/site-packages/casatasks/private/task_sdimaging.py", line 30, in sdimaging
2025-09-16 17:06:39	SEVERE	sdimaging::::casa+	    with sdimaging_worker(**locals()) as worker:
2025-09-16 17:06:39	SEVERE	sdimaging::::casa+	         ^^^^^^^^^^^^^^^^^^^^^^^^^^^^
2025-09-16 17:06:39	SEVERE	sdimaging::::casa+	  File "/scratch/scastro/casa/Tests/reports/casa-6.7.2-15-py3.12.el8/lib/py/lib/python3.12/site-packages/casatasks/private/task_sdimaging.py", line 455, in __init__
2025-09-16 17:06:39	SEVERE	sdimaging::::casa+	    super(sdimaging_worker, self).__init__(**kwargs)
2025-09-16 17:06:39	SEVERE	sdimaging::::casa+	  File "/scratch/scastro/casa/Tests/reports/casa-6.7.2-15-py3.12.el8/lib/py/lib/python3.12/site-packages/casatasks/private/sdutil.py", line 309, in __init__
2025-09-16 17:06:39	SEVERE	sdimaging::::casa+	    self.__set_subtable_name()
2025-09-16 17:06:39	SEVERE	sdimaging::::casa+	  File "/scratch/scastro/casa/Tests/reports/casa-6.7.2-15-py3.12.el8/lib/py/lib/python3.12/site-packages/casatasks/private/sdutil.py", line 366, in __set_subtable_name
2025-09-16 17:06:39	SEVERE	sdimaging::::casa+	    self.open_table(self.infiles[0])
2025-09-16 17:06:39	SEVERE	sdimaging::::casa+	                    ~~~~~~~~~~~~^^^
2025-09-16 17:06:39	SEVERE	sdimaging::::casa+	IndexError: list index out of range
2025-09-16 17:06:39	SEVERE	sdimaging::::casa	list index out of range
2025-09-16 17:06:39	SEVERE	sdimaging::::casa	Task sdimaging raised an exception of class IndexError with the following message: list index out of range
