2025-09-16 17:27:17	SEVERE	sdsmooth::::casa	Traceback (most recent call last):
2025-09-16 17:27:17	SEVERE	sdsmooth::::casa+	             ^^^^^^^^^^^^^^^^^^^^^
2025-09-16 17:27:17	SEVERE	sdsmooth::::casa+	  File "/scratch/scastro/casa/Tests/reports/casa-6.7.2-15-py3.12.el8/lib/py/lib/python3.12/site-packages/casatasks/private/task_sdsmooth.py", line 29, in sdsmooth
2025-09-16 17:27:17	SEVERE	sdsmooth::::casa+	    raise ValueError(errmsg)
2025-09-16 17:27:17	SEVERE	sdsmooth::::casa+	ValueError: tsdsmooth_test.ms_out exists.
2025-09-16 17:27:17	SEVERE	sdsmooth::::casa	tsdsmooth_test.ms_out exists.
2025-09-16 17:27:17	SEVERE	sdsmooth::::casa	Task sdsmooth raised an exception of class ValueError with the following message: tsdsmooth_test.ms_out exists.
