2025-09-16 16:59:51	SEVERE	sdatmcor::::casa	Specified outfile already exist.
2025-09-16 16:59:51	SEVERE	sdatmcor::::casa	Traceback (most recent call last):
2025-09-16 16:59:51	SEVERE	sdatmcor::::casa+	             ^^^^^^^^^^^^^^^^^^^^^
2025-09-16 16:59:51	SEVERE	sdatmcor::::casa+	  File "/scratch/scastro/casa/Tests/reports/casa-6.7.2-15-py3.12.el8/lib/py/lib/python3.12/site-packages/casatasks/private/task_sdatmcor.py", line 652, in sdatmcor
2025-09-16 16:59:51	SEVERE	sdatmcor::::casa+	    raise Exception(errmsg)
2025-09-16 16:59:51	SEVERE	sdatmcor::::casa+	Exception: Specified outfile already exist.
2025-09-16 16:59:51	SEVERE	sdatmcor::::casa	Specified outfile already exist.
2025-09-16 16:59:51	SEVERE	sdatmcor::::casa	Task sdatmcor raised an exception of class Exception with the following message: Specified outfile already exist.
