2025-09-16 17:01:27	SEVERE	sdbaseline::::casa	Traceback (most recent call last):
2025-09-16 17:01:27	SEVERE	sdbaseline::::casa+	  File "/scratch/scastro/casa/Tests/reports/casa-6.7.2-15-py3.12.el8/lib/py/lib/python3.12/site-packages/casatasks/private/task_sdbaseline.py", line 368, in check_fftthresh
2025-09-16 17:01:27	SEVERE	sdbaseline::::casa+	    if (float(fftthresh) <= 0.0):
2025-09-16 17:01:27	SEVERE	sdbaseline::::casa+	        ^^^^^^^^^^^^^^^^
2025-09-16 17:01:27	SEVERE	sdbaseline::::casa+	ValueError: could not convert string to float: ''
2025-09-16 17:01:27	SEVERE	sdbaseline::::casa+	
2025-09-16 17:01:27	SEVERE	sdbaseline::::casa+	During handling of the above exception, another exception occurred:
2025-09-16 17:01:27	SEVERE	sdbaseline::::casa+	
2025-09-16 17:01:27	SEVERE	sdbaseline::::casa+	Traceback (most recent call last):
2025-09-16 17:01:27	SEVERE	sdbaseline::::casa+	             ^^^^^^^^^^^^^^^^^^^^^
2025-09-16 17:01:27	SEVERE	sdbaseline::::casa+	  File "/scratch/scastro/casa/Tests/reports/casa-6.7.2-15-py3.12.el8/lib/py/lib/python3.12/site-packages/casatasks/private/task_sdbaseline.py", line 54, in sdbaseline
2025-09-16 17:01:27	SEVERE	sdbaseline::::casa+	    temp_outfile = _do_fit(infile, datacolumn, antenna, field, spw, timerange, scan,
2025-09-16 17:01:27	SEVERE	sdbaseline::::casa+	                   ^^^^^^^^^^^^^^^^^^^^^^^^^^^^^^^^^^^^^^^^^^^^^^^^^^^^^^^^^^^^^^^^^
2025-09-16 17:01:27	SEVERE	sdbaseline::::casa+	  File "/scratch/scastro/casa/Tests/reports/casa-6.7.2-15-py3.12.el8/lib/py/lib/python3.12/site-packages/casatasks/private/task_sdbaseline.py", line 512, in _do_fit
2025-09-16 17:01:27	SEVERE	sdbaseline::::casa+	    check_fftthresh(fftthresh)
2025-09-16 17:01:27	SEVERE	sdbaseline::::casa+	  File "/scratch/scastro/casa/Tests/reports/casa-6.7.2-15-py3.12.el8/lib/py/lib/python3.12/site-packages/casatasks/private/task_sdbaseline.py", line 371, in check_fftthresh
2025-09-16 17:01:27	SEVERE	sdbaseline::::casa+	    raise ValueError('fftthresh has a wrong format.')
2025-09-16 17:01:27	SEVERE	sdbaseline::::casa+	ValueError: fftthresh has a wrong format.
2025-09-16 17:01:27	SEVERE	sdbaseline::::casa	fftthresh has a wrong format.
2025-09-16 17:01:27	SEVERE	sdbaseline::::casa	Task sdbaseline raised an exception of class ValueError with the following message: fftthresh has a wrong format.
