{"name": "test_incorrectRefTime", "status": "passed", "description": "test7: Does a standard fixplanets with wrong parameter reftime give the expected error", "attachments": [{"name": "stderr", "source": "77d73983-b99a-4ff2-91a1-59f03dea77a6-attachment.txt", "type": "text/plain"}], "start": 1758037327812, "stop": 1758037329496, "uuid": "8d6b5be3-8cef-493c-85f2-ae965deb517b", "historyId": "fea099443dbe6144811a421c50f3ab5f", "testCaseId": "fea099443dbe6144811a421c50f3ab5f", "fullName": "casatasks.test_task_fixplanets.fixplanets_test#test_incorrectRefTime", "labels": [{"name": "parentSuite", "value": "casatasks"}, {"name": "suite", "value": "test_task_fixplanets"}, {"name": "subSuite", "value": "fixplanets_test"}, {"name": "host", "value": "casa-rockylinux8-amd64-perf07"}, {"name": "thread", "value": "597558-MainThread"}, {"name": "framework", "value": "pytest"}, {"name": "language", "value": "cpython3"}, {"name": "package", "value": "casatasks.test_task_fixplanets"}], "titlePath": ["casatasks", "test_task_fixplanets.py", "fixplanets_test"]}